[RRepo](trustyou)meetups
(trustyou)meetups/python-c/time_quicksort.py:76: error: invalid syntax  [syntax]
Found 1 error in 1 file (checked 11 source files)

[RRepo](samkit-jain)Handwriting-Recognition
Success: no issues found in 3 source files

[RRepo](autozimu)LanguageClient-neovim
(autozimu)LanguageClient-neovim/rplugin/python3/denite/lsp/protocol.py:48: error: "Type[SymbolKind]" has no attribute "_pprint_map"  [attr-defined]
(autozimu)LanguageClient-neovim/rplugin/python3/denite/lsp/protocol.py:55: error: "Type[SymbolKind]" has no attribute "_pprint_map"  [attr-defined]

[RRepo](thenetcircle)dino
(thenetcircle)dino/test/cache/test_interface_implemented.py: error: Duplicate module named 'test_interface_implemented' (also at '/home/bew/archive/typed_project/(thenetcircle)dino/test/db/test_interface_implemented.py')  [misc]
Found 1 error in 1 file (checked 163 source files)

[RRepo](googleapis)synthtool
(googleapis)synthtool/synthtool/languages/ruby.py:60: error: Module has no attribute "replace"  [attr-defined]
Found 1 error in 1 file (checked 27 source files)

[RRepo](BookOwl)nustack
(BookOwl)nustack/nustack/stdlib/Hash.py:8: error: Invalid type comment or annotation  [valid-type]
(BookOwl)nustack/nustack/stdlib/Hash.py:13: error: Invalid type comment or annotation  [valid-type]
(BookOwl)nustack/nustack/stdlib/Hash.py:19: error: Invalid type comment or annotation  [valid-type]
(BookOwl)nustack/nustack/stdlib/Hash.py:25: error: Invalid type comment or annotation  [valid-type]
(BookOwl)nustack/nustack/stdlib/Hash.py:32: error: Invalid type comment or annotation  [valid-type]
(BookOwl)nustack/nustack/stdlib/Hash.py:39: error: Invalid type comment or annotation  [valid-type]
(BookOwl)nustack/nustack/stdlib/IO.py:9: error: Invalid type comment or annotation  [valid-type]
(BookOwl)nustack/nustack/stdlib/IO.py:19: error: Invalid type comment or annotation  [valid-type]
(BookOwl)nustack/nustack/stdlib/IO.py:26: error: Invalid type comment or annotation  [valid-type]
(BookOwl)nustack/nustack/stdlib/IO.py:33: error: Invalid type comment or annotation  [valid-type]
(BookOwl)nustack/nustack/stdlib/IO.py:39: error: Invalid type comment or annotation  [valid-type]
(BookOwl)nustack/nustack/stdlib/Seq.py:8: error: Invalid type comment or annotation  [valid-type]
(BookOwl)nustack/nustack/stdlib/Seq.py:18: error: Invalid type comment or annotation  [valid-type]
(BookOwl)nustack/nustack/stdlib/Seq.py:26: error: Name 'first' already defined on line 17  [no-redef]
(BookOwl)nustack/nustack/stdlib/Seq.py:27: error: Invalid type comment or annotation  [valid-type]
(BookOwl)nustack/nustack/stdlib/Seq.py:36: error: Invalid type comment or annotation  [valid-type]
(BookOwl)nustack/nustack/stdlib/Seq.py:43: error: Invalid type comment or annotation  [valid-type]
(BookOwl)nustack/nustack/stdlib/Seq.py:54: error: Invalid type comment or annotation  [valid-type]
(BookOwl)nustack/nustack/stdlib/Seq.py:61: error: Invalid type comment or annotation  [valid-type]
(BookOwl)nustack/nustack/stdlib/Seq.py:67: error: Invalid type comment or annotation  [valid-type]
(BookOwl)nustack/nustack/stdlib/Seq.py:74: error: Invalid type comment or annotation  [valid-type]
(BookOwl)nustack/nustack/stdlib/Seq.py:81: error: Invalid type comment or annotation  [valid-type]
(BookOwl)nustack/nustack/stdlib/Seq.py:87: error: Invalid type comment or annotation  [valid-type]
(BookOwl)nustack/nustack/stdlib/Seq.py:93: error: Invalid type comment or annotation  [valid-type]
(BookOwl)nustack/nustack/stdlib/Seq.py:100: error: Invalid type comment or annotation  [valid-type]
(BookOwl)nustack/nustack/stdlib/Seq.py:107: error: Invalid type comment or annotation  [valid-type]
(BookOwl)nustack/nustack/stdlib/Seq.py:112: error: Invalid type comment or annotation  [valid-type]
(BookOwl)nustack/nustack/stdlib/Seq.py:117: error: Invalid type comment or annotation  [valid-type]
(BookOwl)nustack/nustack/stdlib/Seq.py:123: error: Invalid type comment or annotation  [valid-type]
(BookOwl)nustack/nustack/stdlib/String.py:22: error: Invalid type comment or annotation  [valid-type]
(BookOwl)nustack/nustack/stdlib/String.py:29: error: Invalid type comment or annotation  [valid-type]
(BookOwl)nustack/nustack/stdlib/String.py:36: error: Invalid type comment or annotation  [valid-type]
(BookOwl)nustack/nustack/stdlib/String.py:43: error: Invalid type comment or annotation  [valid-type]
(BookOwl)nustack/nustack/stdlib/String.py:50: error: Invalid type comment or annotation  [valid-type]
(BookOwl)nustack/nustack/stdlib/String.py:55: error: Name 'to_bytes' already defined on line 49  [no-redef]
(BookOwl)nustack/nustack/stdlib/String.py:56: error: Invalid type comment or annotation  [valid-type]
(BookOwl)nustack/nustack/stdlib/Path.py:13: error: Invalid type comment or annotation  [valid-type]
(BookOwl)nustack/nustack/stdlib/Path.py:18: error: Invalid type comment or annotation  [valid-type]
(BookOwl)nustack/nustack/stdlib/Path.py:23: error: Invalid type comment or annotation  [valid-type]
(BookOwl)nustack/nustack/stdlib/Path.py:30: error: Invalid type comment or annotation  [valid-type]
(BookOwl)nustack/nustack/stdlib/Path.py:35: error: Invalid type comment or annotation  [valid-type]
(BookOwl)nustack/nustack/stdlib/Path.py:37: error: Module has no attribute "mkdirs"; maybe "mkdir" or "makedirs"?  [attr-defined]
(BookOwl)nustack/nustack/stdlib/Path.py:40: error: Invalid type comment or annotation  [valid-type]
(BookOwl)nustack/nustack/stdlib/Path.py:45: error: Invalid type comment or annotation  [valid-type]
(BookOwl)nustack/nustack/stdlib/Path.py:50: error: Invalid type comment or annotation  [valid-type]
(BookOwl)nustack/nustack/stdlib/Path.py:56: error: Invalid type comment or annotation  [valid-type]
(BookOwl)nustack/nustack/stdlib/Path.py:61: error: Invalid type comment or annotation  [valid-type]
(BookOwl)nustack/nustack/stdlib/Path.py:66: error: Invalid type comment or annotation  [valid-type]
(BookOwl)nustack/nustack/stdlib/Path.py:71: error: Invalid type comment or annotation  [valid-type]
(BookOwl)nustack/nustack/stdlib/Path.py:76: error: Invalid type comment or annotation  [valid-type]
(BookOwl)nustack/nustack/stdlib/Path.py:81: error: Invalid type comment or annotation  [valid-type]
(BookOwl)nustack/nustack/stdlib/Path.py:86: error: Invalid type comment or annotation  [valid-type]
(BookOwl)nustack/nustack/stdlib/Path.py:91: error: Invalid type comment or annotation  [valid-type]
(BookOwl)nustack/nustack/stdlib/Path.py:96: error: Invalid type comment or annotation  [valid-type]
(BookOwl)nustack/nustack/stdlib/Shell.py:17: error: Invalid type comment or annotation  [valid-type]
(BookOwl)nustack/nustack/stdlib/Shell.py:22: error: Invalid type comment or annotation  [valid-type]
(BookOwl)nustack/nustack/stdlib/Shell.py:41: error: Invalid type comment or annotation  [valid-type]
(BookOwl)nustack/nustack/stdlib/Time.py:9: error: Invalid type comment or annotation  [valid-type]
(BookOwl)nustack/nustack/stdlib/Time.py:14: error: Invalid type comment or annotation  [valid-type]
(BookOwl)nustack/nustack/stdlib/Time.py:20: error: Invalid type comment or annotation  [valid-type]
(BookOwl)nustack/nustack/stdlib/Time.py:26: error: Invalid type comment or annotation  [valid-type]
(BookOwl)nustack/nustack/stdlib/Math.py:10: error: Invalid type comment or annotation  [valid-type]
(BookOwl)nustack/nustack/stdlib/Math.py:16: error: Invalid type comment or annotation  [valid-type]
(BookOwl)nustack/nustack/stdlib/Math.py:22: error: Invalid type comment or annotation  [valid-type]
(BookOwl)nustack/nustack/stdlib/Math.py:28: error: Invalid type comment or annotation  [valid-type]
(BookOwl)nustack/nustack/stdlib/Math.py:34: error: Invalid type comment or annotation  [valid-type]
(BookOwl)nustack/nustack/stdlib/Math.py:41: error: Invalid type comment or annotation  [valid-type]
(BookOwl)nustack/nustack/stdlib/Math.py:47: error: Invalid type comment or annotation  [valid-type]
(BookOwl)nustack/nustack/stdlib/Math.py:53: error: Invalid type comment or annotation  [valid-type]
(BookOwl)nustack/nustack/stdlib/Math.py:59: error: Invalid type comment or annotation  [valid-type]
(BookOwl)nustack/nustack/stdlib/Math.py:65: error: Invalid type comment or annotation  [valid-type]
(BookOwl)nustack/nustack/stdlib/Math.py:71: error: Invalid type comment or annotation  [valid-type]
(BookOwl)nustack/nustack/stdlib/Math.py:76: error: Name 'cos' already defined on line 64  [no-redef]
(BookOwl)nustack/nustack/stdlib/Math.py:77: error: Invalid type comment or annotation  [valid-type]
(BookOwl)nustack/nustack/stdlib/Math.py:82: error: Name 'cos' already defined on line 76  [no-redef]
(BookOwl)nustack/nustack/stdlib/Math.py:83: error: Invalid type comment or annotation  [valid-type]
(BookOwl)nustack/nustack/stdlib/Math.py:88: error: Name 'sin' already defined on line 70  [no-redef]
(BookOwl)nustack/nustack/stdlib/Math.py:89: error: Invalid type comment or annotation  [valid-type]
(BookOwl)nustack/nustack/stdlib/Math.py:94: error: Name 'cos' already defined on line 64  [no-redef]
(BookOwl)nustack/nustack/stdlib/Math.py:95: error: Invalid type comment or annotation  [valid-type]
(BookOwl)nustack/nustack/stdlib/Math.py:101: error: Invalid type comment or annotation  [valid-type]
(BookOwl)nustack/nustack/stdlib/Math.py:107: error: Invalid type comment or annotation  [valid-type]
(BookOwl)nustack/nustack/stdlib/Math.py:113: error: Invalid type comment or annotation  [valid-type]
(BookOwl)nustack/nustack/stdlib/Math.py:119: error: Invalid type comment or annotation  [valid-type]
(BookOwl)nustack/nustack/stdlib/Math.py:125: error: Invalid type comment or annotation  [valid-type]
(BookOwl)nustack/nustack/stdlib/Turtle.py:11: error: "Callable[[], Any]" has no attribute "started"  [attr-defined]
(BookOwl)nustack/nustack/stdlib/Turtle.py:14: error: Invalid type comment or annotation  [valid-type]
(BookOwl)nustack/nustack/stdlib/Turtle.py:21: error: Invalid type comment or annotation  [valid-type]
(BookOwl)nustack/nustack/stdlib/Turtle.py:29: error: Invalid type comment or annotation  [valid-type]
(BookOwl)nustack/nustack/stdlib/Turtle.py:39: error: Invalid type comment or annotation  [valid-type]
(BookOwl)nustack/nustack/stdlib/Turtle.py:46: error: Invalid type comment or annotation  [valid-type]
(BookOwl)nustack/nustack/stdlib/Turtle.py:53: error: Invalid type comment or annotation  [valid-type]
(BookOwl)nustack/nustack/stdlib/Turtle.py:60: error: Invalid type comment or annotation  [valid-type]
(BookOwl)nustack/nustack/stdlib/Turtle.py:67: error: Invalid type comment or annotation  [valid-type]
(BookOwl)nustack/nustack/stdlib/Turtle.py:74: error: Invalid type comment or annotation  [valid-type]
(BookOwl)nustack/nustack/stdlib/Turtle.py:81: error: Invalid type comment or annotation  [valid-type]
(BookOwl)nustack/nustack/stdlib/Turtle.py:91: error: Invalid type comment or annotation  [valid-type]
(BookOwl)nustack/nustack/stdlib/Turtle.py:98: error: Invalid type comment or annotation  [valid-type]
(BookOwl)nustack/nustack/stdlib/Turtle.py:105: error: Invalid type comment or annotation  [valid-type]
(BookOwl)nustack/nustack/stdlib/Turtle.py:112: error: Invalid type comment or annotation  [valid-type]
(BookOwl)nustack/nustack/stdlib/Turtle.py:119: error: Invalid type comment or annotation  [valid-type]
(BookOwl)nustack/nustack/stdlib/Turtle.py:126: error: Invalid type comment or annotation  [valid-type]
(BookOwl)nustack/nustack/stdlib/Turtle.py:133: error: Invalid type comment or annotation  [valid-type]
(BookOwl)nustack/nustack/stdlib/Turtle.py:140: error: Invalid type comment or annotation  [valid-type]
(BookOwl)nustack/nustack/stdlib/Turtle.py:147: error: Invalid type comment or annotation  [valid-type]
(BookOwl)nustack/nustack/stdlib/Turtle.py:154: error: Invalid type comment or annotation  [valid-type]
(BookOwl)nustack/nustack/stdlib/Turtle.py:161: error: Invalid type comment or annotation  [valid-type]
(BookOwl)nustack/nustack/stdlib/Turtle.py:168: error: Invalid type comment or annotation  [valid-type]
(BookOwl)nustack/nustack/stdlib/Turtle.py:175: error: Invalid type comment or annotation  [valid-type]
(BookOwl)nustack/nustack/stdlib/Turtle.py:184: error: Invalid type comment or annotation  [valid-type]
(BookOwl)nustack/nustack/stdlib/Turtle.py:193: error: Invalid type comment or annotation  [valid-type]
(BookOwl)nustack/nustack/stdlib/Turtle.py:200: error: Invalid type comment or annotation  [valid-type]
(BookOwl)nustack/nustack/stdlib/Turtle.py:207: error: Invalid type comment or annotation  [valid-type]
(BookOwl)nustack/nustack/stdlib/Turtle.py:212: error: Invalid type comment or annotation  [valid-type]
(BookOwl)nustack/nustack/stdlib/Turtle.py:214: error: Module has no attribute "bye"  [attr-defined]
(BookOwl)nustack/nustack/stdlib/Requests.py:25: error: Invalid type comment or annotation  [valid-type]
(BookOwl)nustack/nustack/stdlib/Requests.py:31: error: Name 'get' already defined on line 24  [no-redef]
(BookOwl)nustack/nustack/stdlib/Requests.py:32: error: Invalid type comment or annotation  [valid-type]
(BookOwl)nustack/nustack/stdlib/Requests.py:38: error: Name 'get' already defined on line 24  [no-redef]
(BookOwl)nustack/nustack/stdlib/Requests.py:39: error: Invalid type comment or annotation  [valid-type]
(BookOwl)nustack/nustack/stdlib/Requests.py:45: error: Name 'get' already defined on line 24  [no-redef]
(BookOwl)nustack/nustack/stdlib/Requests.py:46: error: Invalid type comment or annotation  [valid-type]
(BookOwl)nustack/nustack/stdlib/Requests.py:52: error: Name 'get' already defined on line 24  [no-redef]
(BookOwl)nustack/nustack/stdlib/Requests.py:53: error: Invalid type comment or annotation  [valid-type]
(BookOwl)nustack/nustack/stdlib/Requests.py:59: error: Name 'get' already defined on line 24  [no-redef]
(BookOwl)nustack/nustack/stdlib/Requests.py:60: error: Invalid type comment or annotation  [valid-type]
(BookOwl)nustack/nustack/stdlib/Requests.py:68: error: Name 'get' already defined on line 24  [no-redef]
(BookOwl)nustack/nustack/stdlib/Requests.py:69: error: Invalid type comment or annotation  [valid-type]
(BookOwl)nustack/nustack/stdlib/Requests.py:78: error: Invalid type comment or annotation  [valid-type]
Found 129 errors in 10 files (checked 23 source files)

[RRepo](googlefonts)fontbakery
(googlefonts)fontbakery/Lib/fontbakery/reporters/html.py:85: error: Too many arguments for "summary_table"  [call-arg]
(googlefonts)fontbakery/Lib/fontbakery/callable.py:50: error: Decorated property not supported  [misc]
(googlefonts)fontbakery/Lib/fontbakery/callable.py:55: error: Decorated property not supported  [misc]
(googlefonts)fontbakery/Lib/fontbakery/callable.py:64: error: Decorated property not supported  [misc]
Found 4 errors in 2 files (checked 59 source files)

[RRepo](easonnie)flint
Success: no issues found in 2 source files

[RRepo](MikimotoH)DLink_Harvester
(MikimotoH)DLink_Harvester/harvest_utils.py:25: error: Bracketed expression "[...]" is not valid as a type  [misc]
(MikimotoH)DLink_Harvester/harvest_utils.py:25: note: Did you mean "List[...]"?
(MikimotoH)DLink_Harvester/harvest_utils.py:45: error: Bracketed expression "[...]" is not valid as a type  [misc]
(MikimotoH)DLink_Harvester/harvest_utils.py:45: note: Did you mean "List[...]"?
(MikimotoH)DLink_Harvester/harvest_utils.py:76: error: Bracketed expression "[...]" is not valid as a type  [misc]
(MikimotoH)DLink_Harvester/harvest_utils.py:76: note: Did you mean "List[...]"?
(MikimotoH)DLink_Harvester/harvest_utils.py:79: error: "Waiter" has no attribute "elems"; maybe "Elems"?  [attr-defined]
(MikimotoH)DLink_Harvester/harvest_utils.py:176: error: Bracketed expression "[...]" is not valid as a type  [misc]
(MikimotoH)DLink_Harvester/harvest_utils.py:176: note: Did you mean "List[...]"?
(MikimotoH)DLink_Harvester/harvest_utils.py:179: error: "None" has no attribute "find_elements_by_css_selector"  [attr-defined]
(MikimotoH)DLink_Harvester/harvest_utils.py:187: error: "None" has no attribute "execute_script"  [attr-defined]
(MikimotoH)DLink_Harvester/harvest_utils.py:192: error: Incompatible types in assignment (expression has type "float", variable has type "int")  [assignment]
(MikimotoH)DLink_Harvester/harvest_utils.py:197: error: "None" has no attribute "execute_script"  [attr-defined]
(MikimotoH)DLink_Harvester/harvest_utils.py:221: error: Incompatible types in assignment (expression has type "float", variable has type "int")  [assignment]
(MikimotoH)DLink_Harvester/harvest_utils.py:248: error: "None" has no attribute "save_screenshot"  [attr-defined]
(MikimotoH)DLink_Harvester/harvest_utils.py:250: error: "None" has no attribute "page_source"  [attr-defined]
(MikimotoH)DLink_Harvester/web_utils.py:47: error: Syntax error in type annotation  [syntax]
(MikimotoH)DLink_Harvester/web_utils.py:47: note: Suggestion: Use Tuple[T1, ..., Tn] instead of (T1, ..., Tn)
(MikimotoH)DLink_Harvester/web_utils.py:109: error: Incompatible types in assignment (expression has type "Callable[[MyHTTPRedirectHandler, Any, Any, Any, Any, Any], Any]", base class "HTTPRedirectHandler" defined the type as "Callable[[HTTPRedirectHandler, Request, IO[str], int, int, Mapping[str, str]], Optional[Any]]")  [assignment]
(MikimotoH)DLink_Harvester/netgear_crawler2.py:37: error: Argument 2 for "super" not an instance of argument 1  [misc]
(MikimotoH)DLink_Harvester/netgear_crawler2.py:64: error: Name 'timeElapsed' is not defined  [name-defined]
(MikimotoH)DLink_Harvester/netgear_crawler2.py:64: error: Name 'beginTime' is not defined  [name-defined]
(MikimotoH)DLink_Harvester/netgear_crawler2.py:106: error: Bracketed expression "[...]" is not valid as a type  [misc]
(MikimotoH)DLink_Harvester/netgear_crawler2.py:106: note: Did you mean "List[...]"?
(MikimotoH)DLink_Harvester/netgear_crawler2.py:114: error: Name 'begin' is not defined  [name-defined]
(MikimotoH)DLink_Harvester/netgear_cn_crawler.py:127: error: Syntax error in type annotation  [syntax]
(MikimotoH)DLink_Harvester/netgear_cn_crawler.py:127: note: Suggestion: Use Tuple[T1, ..., Tn] instead of (T1, ..., Tn)
(MikimotoH)DLink_Harvester/zyxel_us_crawler.py:135: error: Syntax error in type annotation  [syntax]
(MikimotoH)DLink_Harvester/zyxel_us_crawler.py:135: note: Suggestion: Use Tuple[T1, ..., Tn] instead of (T1, ..., Tn)
(MikimotoH)DLink_Harvester/dlink_ftp.dlink.eu_filelist2.py:94: error: No overload variant of "__setitem__" of "list" matches argument types "int", "Tuple[Any, Any, Any, Any, Any, Any, Any]"  [call-overload]
(MikimotoH)DLink_Harvester/dlink_ftp.dlink.eu_filelist2.py:94: note: Possible overload variants:
(MikimotoH)DLink_Harvester/dlink_ftp.dlink.eu_filelist2.py:94: note:     def __setitem__(self, int, List[Any]) -> None
(MikimotoH)DLink_Harvester/dlink_ftp.dlink.eu_filelist2.py:94: note:     def __setitem__(self, slice, Iterable[List[Any]]) -> None
(MikimotoH)DLink_Harvester/dlink_ftp.dlink.eu_filelist2.py:100: error: Module has no attribute "error"  [attr-defined]
Found 23 errors in 6 files (checked 34 source files)

[RRepo](hadware)voxpopuli
(hadware)voxpopuli/voxpopuli/phonemes.py:36: error: List comprehension has incompatible type List[Tuple[float, int]]; expected List[Tuple[int, int]]  [misc]
Found 1 error in 1 file (checked 4 source files)

[RRepo](biosustain)venom
(biosustain)venom/venom/common/fields.py: error: Duplicate module named 'fields' (also at '/home/bew/archive/typed_project/(biosustain)venom/venom/fields.py')  [misc]
(biosustain)venom/venom/common/fields.py: error: Are you missing an __init__.py?  [misc]
Found 2 errors in 1 file (checked 50 source files)

[RRepo](aguinane)nem-reader
(aguinane)nem-reader/tests/test_file_outputs.py:9: error: Module 'nemreader' has no attribute 'output_as_csv'  [attr-defined]
(aguinane)nem-reader/nemreader/nem_reader.py:42: error: Incompatible types in assignment (expression has type "TextIO", variable has type "List[str]")  [assignment]
(aguinane)nem-reader/nemreader/nem_reader.py:56: error: Need type annotation for 'readings' (hint: "readings: Dict[<type>, <type>] = ...")  [var-annotated]
(aguinane)nem-reader/nemreader/nem_reader.py:57: error: Need type annotation for 'trans' (hint: "trans: Dict[<type>, <type>] = ...")  [var-annotated]
Found 4 errors in 2 files (checked 9 source files)

[RRepo](jaantollander)CrowdDynamics
(jaantollander)CrowdDynamics/crowddynamics/io.py:10: error: Module 'io' has no attribute 'StringIO'  [attr-defined]
(jaantollander)CrowdDynamics/crowddynamics/io.py:10: error: Module 'io' has no attribute 'StringIO'  [attr-defined]
(jaantollander)CrowdDynamics/crowddynamics/core/steering/quickest_path.py:144: error: Variable "crowddynamics.core.steering.quickest_path.DistanceMap" is not valid as a type  [valid-type]

[RRepo](s0hvaperuna)Not-a-bot
(s0hvaperuna)Not-a-bot/bot/server.py: error: Duplicate module named 'server' (also at '/home/bew/archive/typed_project/(s0hvaperuna)Not-a-bot/cogs/server.py')  [misc]
Found 1 error in 1 file (checked 46 source files)

[RRepo](conversationai)conversationai-models
(conversationai)conversationai-models/data_preparation/preprocessing/preprocessing.py:69: error: invalid syntax  [syntax]
Found 1 error in 1 file (checked 58 source files)

[RRepo](nschloe)quadpy
(nschloe)quadpy/quadpy/nball/_stroud_1967_7.py:4: error: No parent module -- cannot perform relative import  [misc]
Found 1 error in 1 file (checked 245 source files)

[RRepo](coldfix)pystif
(coldfix)pystif/pystif/core/geom.py:143: error: Name 'search_ensure_vertex' already defined on line 99  [no-redef]
(coldfix)pystif/pystif/equiv.py:33: error: Name 'SymmetryGroup' is not defined  [name-defined]
(coldfix)pystif/test/test_it.py:31: error: Name 'test_elemental_inequalities_2' already defined on line 23  [no-redef]
Found 3 errors in 3 files (checked 34 source files)

[RRepo](and800)aioreloader
(and800)aioreloader/aioreloader/_contents.py:19: error: Cannot assign multiple types to name "hook_type" without an explicit "Type[...]" annotation  [misc]
(and800)aioreloader/aioreloader/_contents.py:53: error: Need type annotation for 'modify_times' (hint: "modify_times: Dict[<type>, <type>] = ...")  [var-annotated]
Found 2 errors in 1 file (checked 1 source file)

[RRepo](GregorCH)ipet
(GregorCH)ipet/ipetgui/IPETParserWindow.py:26: error: No parent module -- cannot perform relative import  [misc]
Found 1 error in 1 file (checked 46 source files)

[RRepo](pyGrowler)Growler
(pyGrowler)Growler/growler/core/responder.py: error: Duplicate module named 'responder' (also at '/home/bew/archive/typed_project/(pyGrowler)Growler/growler/http/responder.py')  [misc]
Found 1 error in 1 file (checked 52 source files)

[RRepo](Jamjomjara)snu-artoon
(Jamjomjara)snu-artoon/AnnotationToXMLConverter/FDDBAnnotationReader.py:18: error: No overload variant of "__setitem__" of "list" matches argument types "int", "float"  [call-overload]
(Jamjomjara)snu-artoon/AnnotationToXMLConverter/FDDBAnnotationReader.py:18: note: Possible overload variants:
(Jamjomjara)snu-artoon/AnnotationToXMLConverter/FDDBAnnotationReader.py:18: note:     def __setitem__(self, int, str) -> None
(Jamjomjara)snu-artoon/AnnotationToXMLConverter/FDDBAnnotationReader.py:18: note:     def __setitem__(self, slice, Iterable[str]) -> None
(Jamjomjara)snu-artoon/AnnotationToXMLConverter/FDDBAnnotationReader.py:19: error: Unsupported operand types for - ("str" and "float")  [operator]
(Jamjomjara)snu-artoon/AnnotationToXMLConverter/FDDBAnnotationReader.py:19: error: Unsupported operand types for / ("str" and "int")  [operator]
(Jamjomjara)snu-artoon/AnnotationToXMLConverter/FDDBAnnotationReader.py:20: error: Unsupported operand types for - ("str" and "float")  [operator]
(Jamjomjara)snu-artoon/AnnotationToXMLConverter/FDDBAnnotationReader.py:20: error: Unsupported operand types for / ("str" and "int")  [operator]
(Jamjomjara)snu-artoon/AnnotationToXMLConverter/FDDBAnnotationReader.py:21: error: Unsupported operand types for / ("str" and "int")  [operator]
(Jamjomjara)snu-artoon/AnnotationToXMLConverter/FDDBAnnotationReader.py:21: error: Unsupported operand types for + ("str" and "float")  [operator]
(Jamjomjara)snu-artoon/AnnotationToXMLConverter/FDDBAnnotationReader.py:22: error: Unsupported operand types for / ("str" and "int")  [operator]
(Jamjomjara)snu-artoon/AnnotationToXMLConverter/FDDBAnnotationReader.py:22: error: Unsupported operand types for + ("str" and "float")  [operator]
Found 9 errors in 1 file (checked 5 source files)

[RRepo](KrusnikViers)Zordon
(KrusnikViers)Zordon/app/handlers/impl/broadcasts.py:12: error: Name '_' is not defined  [name-defined]
(KrusnikViers)Zordon/app/handlers/impl/broadcasts.py:16: error: Name '_' is not defined  [name-defined]
(KrusnikViers)Zordon/app/handlers/impl/broadcasts.py:18: error: Name '_' is not defined  [name-defined]
(KrusnikViers)Zordon/app/handlers/impl/broadcasts.py:33: error: Syntax error in type annotation  [syntax]
(KrusnikViers)Zordon/app/handlers/impl/broadcasts.py:33: note: Suggestion: Use Tuple[T1, ..., Tn] instead of (T1, ..., Tn)
(KrusnikViers)Zordon/app/handlers/impl/broadcasts.py:50: error: Name '_' is not defined  [name-defined]
(KrusnikViers)Zordon/app/handlers/impl/broadcasts.py:52: error: Name '_' is not defined  [name-defined]
(KrusnikViers)Zordon/app/handlers/impl/broadcasts.py:55: error: Name '_' is not defined  [name-defined]
(KrusnikViers)Zordon/app/handlers/impl/broadcasts.py:63: error: Name '_' is not defined  [name-defined]
(KrusnikViers)Zordon/app/handlers/impl/broadcasts.py:67: error: Name '_' is not defined  [name-defined]
(KrusnikViers)Zordon/app/handlers/impl/broadcasts.py:69: error: Name '_' is not defined  [name-defined]
(KrusnikViers)Zordon/app/handlers/impl/broadcasts.py:85: error: Name '_' is not defined  [name-defined]
(KrusnikViers)Zordon/app/handlers/impl/basic.py:9: error: Name '_' is not defined  [name-defined]
(KrusnikViers)Zordon/app/handlers/impl/basic.py:14: error: Name '_' is not defined  [name-defined]
(KrusnikViers)Zordon/app/handlers/impl/basic.py:20: error: Name '_' is not defined  [name-defined]
(KrusnikViers)Zordon/app/handlers/impl/basic.py:25: error: Name '_' is not defined  [name-defined]
(KrusnikViers)Zordon/app/handlers/impl/basic.py:30: error: Name '_' is not defined  [name-defined]
(KrusnikViers)Zordon/app/handlers/impl/routing.py:10: error: Name '_' is not defined  [name-defined]
(KrusnikViers)Zordon/app/handlers/impl/routing.py:18: error: Name '_' is not defined  [name-defined]
(KrusnikViers)Zordon/app/handlers/context.py:52: error: Syntax error in type annotation  [syntax]
(KrusnikViers)Zordon/app/handlers/context.py:52: note: Suggestion: Use Tuple[T1, ..., Tn] instead of (T1, ..., Tn)
(KrusnikViers)Zordon/tests/handlers/impl/test_broadcast.py:18: error: Name 'Group' is not defined  [name-defined]
(KrusnikViers)Zordon/tests/handlers/impl/test_broadcast.py:19: error: Name 'User' is not defined  [name-defined]
(KrusnikViers)Zordon/app/handlers/util/reports.py:31: error: "None" has no attribute "bot"  [attr-defined]
(KrusnikViers)Zordon/app/handlers/util/reports.py:37: error: "None" has no attribute "bot"  [attr-defined]
(KrusnikViers)Zordon/app/i18n/updater.py:44: error: Need type annotation for 'strings_dict' (hint: "strings_dict: Dict[<type>, <type>] = ...")  [var-annotated]
Found 24 errors in 7 files (checked 32 source files)

[RRepo](nanoporetech)bwapy
(nanoporetech)bwapy/bwapy/libbwa.py:258: error: Need type annotation for 'alignments'  [var-annotated]
Found 1 error in 1 file (checked 1 source file)

[RRepo](nicfit)nicfit.py
(nicfit)nicfit.py/nicfit/__main__.py:11: error: No parent module -- cannot perform relative import  [misc]
Found 1 error in 1 file (checked 41 source files)

[RRepo](pablotcarreira)django-arangodb
(pablotcarreira)django-arangodb/arangodb_driver/compiler.py:19: error: Syntax error in type annotation  [syntax]
(pablotcarreira)django-arangodb/arangodb_driver/compiler.py:19: note: Suggestion: Use Tuple[T1, ..., Tn] instead of (T1, ..., Tn)
Found 1 error in 1 file (checked 14 source files)

[RRepo](PeerAssets)pypeerassets
(PeerAssets)pypeerassets/pypeerassets/voting.py:20: error: Name 'unhexlify' is not defined  [name-defined]
(PeerAssets)pypeerassets/pypeerassets/voting.py:89: error: Name 'unhexlify' is not defined  [name-defined]
(PeerAssets)pypeerassets/pypeerassets/voting.py:130: error: Name 'unhexlify' is not defined  [name-defined]
(PeerAssets)pypeerassets/pypeerassets/voting.py:131: error: Name 'unhexlify' is not defined  [name-defined]
(PeerAssets)pypeerassets/pypeerassets/voting.py:170: error: Name 'unhexlify' is not defined  [name-defined]
(PeerAssets)pypeerassets/pypeerassets/voting.py:171: error: Name 'unhexlify' is not defined  [name-defined]
(PeerAssets)pypeerassets/pypeerassets/transactions.py:152: error: Cannot determine type of 'ins'  [has-type]
(PeerAssets)pypeerassets/pypeerassets/transactions.py:160: error: Cannot determine type of 'outs'  [has-type]
(PeerAssets)pypeerassets/pypeerassets/__main__.py:180: error: Incompatible types in assignment (expression has type "Generator[Any, None, None]", variable has type "List[Any]")  [assignment]
Found 9 errors in 3 files (checked 22 source files)

[RRepo](googleapis)sample-tester
(googleapis)sample-tester/sampletester/convention/__init__.py:40: error: Module has no attribute "test_environments"  [attr-defined]
(googleapis)sample-tester/sampletester/convention/tag.py:203: error: Not all arguments converted during string formatting  [str-format]
(googleapis)sample-tester/sampletester/cli.py:125: error: Incompatible types in assignment (expression has type "str", variable has type "int")  [assignment]
(googleapis)sample-tester/tests/convention/tag_test.py:73: error: Name 'test_invocation_with_placeholder' already defined on line 58  [no-redef]
(googleapis)sample-tester/sampletester/convention/cloud/__init__.py:20: error: Not all arguments converted during string formatting  [str-format]
(googleapis)sample-tester/sampletester/testplan.py:153: error: "Visitor" has no attribute "visit_test_case"; maybe "visit_testcase"?  [attr-defined]
(googleapis)sample-tester/sampletester/testplan.py:181: error: Signature of "visit_environment" incompatible with supertype "Visitor"  [override]
(googleapis)sample-tester/sampletester/testplan.py:190: error: Signature of "visit_suite" incompatible with supertype "Visitor"  [override]
(googleapis)sample-tester/sampletester/testplan.py:195: error: Signature of "visit_testcase" incompatible with supertype "Visitor"  [override]
(googleapis)sample-tester/sampletester/testplan.py:201: error: Signature of "visit_suite_end" incompatible with supertype "Visitor"  [override]
(googleapis)sample-tester/sampletester/testplan.py:206: error: Signature of "visit_environment_end" incompatible with supertype "Visitor"  [override]
(googleapis)sample-tester/gen_manifest/gen_manifest.py:222: error: Syntax error in type annotation  [syntax]
(googleapis)sample-tester/gen_manifest/gen_manifest.py:222: note: Suggestion: Use Tuple[T1, ..., Tn] instead of (T1, ..., Tn)
(googleapis)sample-tester/tests/gen_manifest/gen_manifest_test.py:21: error: Module 'gen_manifest' has no attribute 'gen_manifest'  [attr-defined]
Found 13 errors in 8 files (checked 15 source files)

[RRepo](jacebrowning)doorstop
(jacebrowning)doorstop/doorstop/server/main.py:24: error: Invalid "type: ignore" comment  [syntax]
Found 1 error in 1 file (checked 36 source files)

[RRepo](corradio)electricitymap
(corradio)electricitymap/parsers/JP.py:8: error: No parent module -- cannot perform relative import  [misc]
Found 1 error in 1 file (checked 43 source files)

[RRepo](chiaki64)Windless
(chiaki64)Windless/core/components/router.py:14: error: Name 'public' is not defined  [name-defined]
(chiaki64)Windless/core/components/router.py:15: error: Name 'public' is not defined  [name-defined]
(chiaki64)Windless/core/components/router.py:16: error: Name 'public' is not defined  [name-defined]
(chiaki64)Windless/core/components/router.py:17: error: Name 'public' is not defined  [name-defined]
(chiaki64)Windless/core/components/router.py:18: error: Name 'public' is not defined  [name-defined]
(chiaki64)Windless/core/components/router.py:19: error: Name 'public' is not defined  [name-defined]
(chiaki64)Windless/core/components/router.py:21: error: Name 'public' is not defined  [name-defined]
(chiaki64)Windless/core/components/router.py:22: error: Name 'public' is not defined  [name-defined]
(chiaki64)Windless/core/components/router.py:25: error: Name 'public' is not defined  [name-defined]
(chiaki64)Windless/core/components/router.py:33: error: Name 'auth' is not defined  [name-defined]
(chiaki64)Windless/core/components/router.py:34: error: Name 'auth' is not defined  [name-defined]
(chiaki64)Windless/core/components/router.py:37: error: Name 'auth' is not defined  [name-defined]
(chiaki64)Windless/core/components/router.py:40: error: Name 'auth' is not defined  [name-defined]
(chiaki64)Windless/core/components/router.py:48: error: Name 'backend' is not defined  [name-defined]
(chiaki64)Windless/core/components/router.py:49: error: Name 'backend' is not defined  [name-defined]
(chiaki64)Windless/core/components/router.py:52: error: Name 'backend' is not defined  [name-defined]
(chiaki64)Windless/core/components/router.py:53: error: Name 'backend' is not defined  [name-defined]
(chiaki64)Windless/core/components/router.py:54: error: Name 'backend' is not defined  [name-defined]
(chiaki64)Windless/core/components/router.py:55: error: Name 'backend' is not defined  [name-defined]
(chiaki64)Windless/core/components/router.py:56: error: Name 'backend' is not defined  [name-defined]
(chiaki64)Windless/core/components/router.py:57: error: Name 'backend' is not defined  [name-defined]
(chiaki64)Windless/core/components/router.py:58: error: Name 'backend' is not defined  [name-defined]
(chiaki64)Windless/core/components/router.py:59: error: Name 'backend' is not defined  [name-defined]

[RRepo](5j9)yadkard
(5j9)yadkard/lib/commons.py:215: error: Invalid type comment or annotation  [valid-type]
(5j9)yadkard/test/__init__.py:20: error: 'staticmethod' used with a non-method  [misc]
(5j9)yadkard/test/__init__.py:73: error: Cannot assign to a method  [assignment]
(5j9)yadkard/test/__init__.py:73: error: Incompatible types in assignment (expression has type "Callable[[Any, Any, Any, KwArg(Any)], Any]", variable has type "Callable[[Session, str, Union[str, bytes, str], Union[None, bytes, MutableMapping[str, str]], Union[None, str, bytes, MutableMapping[str, Any], MutableMapping[str, Any], Iterable[Tuple[str, Optional[str]]], IO[Any]], Optional[MutableMapping[str, str]], Union[None, RequestsCookieJar, MutableMapping[str, str]], Optional[MutableMapping[str, IO[Any]]], Union[None, Tuple[str, str], AuthBase, Callable[[Request], Request]], Union[None, float, Tuple[float, float]], Optional[bool], Optional[MutableMapping[str, str]], Optional[MutableMapping[str, Union[Iterable[Callable[[Response], Any]], Callable[[Response], Any]]]], Optional[bool], Union[None, bool, str], Union[str, Tuple[str, str], None], Optional[Any]], Response]")  [assignment]

[RRepo](PyAndy)Py3NES
(PyAndy)Py3NES/cpu.py:30: error: misplaced type annotation  [syntax]
Found 1 error in 1 file (checked 15 source files)

[RRepo](igorcoding)asynctnt
(igorcoding)asynctnt/asynctnt/_testbase.py:15: error: Module 'asynctnt' has no attribute 'TarantoolTuple'  [attr-defined]
(igorcoding)asynctnt/asynctnt/_testbase.py:36: error: Unsupported dynamic base class "type"  [misc]
(igorcoding)asynctnt/asynctnt/_testbase.py:190: error: Name 'asynctnt.Connection' is not defined  [name-defined]
(igorcoding)asynctnt/temp/demo/demo.py:55: error: Module has no attribute "run"  [attr-defined]
(igorcoding)asynctnt/temp/with_crash.py:33: error: Module has no attribute "run"  [attr-defined]

[RRepo](dashwav)nano-chan
(dashwav)nano-chan/cogs/rng.py:34: error: unexpected EOF while parsing  [syntax]
Found 1 error in 1 file (checked 15 source files)

[RRepo](SQbQxeKd3JHD8)simple_ConTeXt
(SQbQxeKd3JHD8)simple_ConTeXt/scripts/log.py:3: error: No parent module -- cannot perform relative import  [misc]
(SQbQxeKd3JHD8)simple_ConTeXt/scripts/log.py:4: error: No parent module -- cannot perform relative import  [misc]
Found 2 errors in 1 file (checked 24 source files)

[RRepo](modm-io)modm-devices
(modm-io)modm-devices/tools/device/modm_devices/parser.py:10: error: No parent module -- cannot perform relative import  [misc]
Found 1 error in 1 file (checked 22 source files)

[RRepo](team-phoenix)Phoenix
(team-phoenix)Phoenix/frontend/python/updaters/updateExtension.py:13: error: Incompatible types in assignment (expression has type "Tuple[Tuple[str, str], Tuple[str, str]]", variable has type "Optional[List[Any]]")  [assignment]
(team-phoenix)Phoenix/frontend/python/updaters/updateSystemToCore.py:9: error: Incompatible types in assignment (expression has type "Tuple[Tuple[str, str], Tuple[str, str]]", variable has type "Optional[List[Any]]")  [assignment]
(team-phoenix)Phoenix/frontend/python/updaters/updateSystemToCore.py:69: error: Name 'columns' is not defined  [name-defined]
(team-phoenix)Phoenix/frontend/python/updaters/updateSystem.py:11: error: Incompatible types in assignment (expression has type "Tuple[Tuple[str, str], Tuple[str, str], Tuple[str, str], Tuple[str, str], Tuple[str, str], Tuple[str, str], Tuple[str, str]]", variable has type "Optional[List[Any]]")  [assignment]
(team-phoenix)Phoenix/frontend/python/updaters/updateFirmware.py:10: error: Incompatible types in assignment (expression has type "Tuple[Tuple[str, str], Tuple[str, str], Tuple[str, str], Tuple[str, str], Tuple[str, str], Tuple[str, str]]", variable has type "Optional[List[Any]]")  [assignment]
(team-phoenix)Phoenix/frontend/python/updaters/updateOpenVGDBToSystem.py:12: error: Incompatible types in assignment (expression has type "Tuple[Tuple[str, str], Tuple[str, str]]", variable has type "Optional[List[Any]]")  [assignment]
(team-phoenix)Phoenix/frontend/python/updaters/updateOpenVGDBToSystem.py:34: error: Name 'columns' is not defined  [name-defined]
(team-phoenix)Phoenix/frontend/python/updaters/updateCore.py:15: error: Incompatible types in assignment (expression has type "Tuple[Tuple[str, str], Tuple[str, str], Tuple[str, str], Tuple[str, str], Tuple[str, str]]", variable has type "Optional[List[Any]]")  [assignment]
(team-phoenix)Phoenix/frontend/python/updaters/updateCore.py:57: error: Name 'columns' is not defined  [name-defined]
(team-phoenix)Phoenix/frontend/python/updaters/updateRomHeaderOffset.py:11: error: Incompatible types in assignment (expression has type "Tuple[Tuple[str, str], Tuple[str, str], Tuple[str, str], Tuple[str, str]]", variable has type "Optional[List[Any]]")  [assignment]
(team-phoenix)Phoenix/frontend/python/updaters/sqldatabase.py:30: error: "None" has no attribute "execute"  [attr-defined]
(team-phoenix)Phoenix/frontend/python/updaters/sqldatabase.py:39: error: Incompatible types in assignment (expression has type "Connection", variable has type "None")  [assignment]
(team-phoenix)Phoenix/frontend/python/updaters/sqldatabase.py:40: error: "None" has no attribute "cursor"  [attr-defined]
(team-phoenix)Phoenix/frontend/python/updaters/sqldatabase.py:71: error: "None" has no attribute "execute"  [attr-defined]
(team-phoenix)Phoenix/frontend/python/updaters/sqldatabase.py:93: error: "None" has no attribute "execute"  [attr-defined]
(team-phoenix)Phoenix/frontend/python/updaters/sqldatabase.py:101: error: "None" has no attribute "execute"  [attr-defined]
(team-phoenix)Phoenix/frontend/python/updaters/retrieve_core_info.py:30: error: Need type annotation for 'output'  [var-annotated]
(team-phoenix)Phoenix/frontend/python/updaters/retrieve_core_info.py:61: error: No overload variant of "__setitem__" of "list" matches argument types "int", "bool"  [call-overload]
(team-phoenix)Phoenix/frontend/python/updaters/retrieve_core_info.py:61: note: Possible overload variants:
(team-phoenix)Phoenix/frontend/python/updaters/retrieve_core_info.py:61: note:     def __setitem__(self, int, str) -> None
(team-phoenix)Phoenix/frontend/python/updaters/retrieve_core_info.py:61: note:     def __setitem__(self, slice, Iterable[str]) -> None
(team-phoenix)Phoenix/frontend/python/updaters/retrieve_core_info.py:63: error: No overload variant of "__setitem__" of "list" matches argument types "int", "bool"  [call-overload]
(team-phoenix)Phoenix/frontend/python/updaters/retrieve_core_info.py:63: note: Possible overload variants:
(team-phoenix)Phoenix/frontend/python/updaters/retrieve_core_info.py:63: note:     def __setitem__(self, int, str) -> None
(team-phoenix)Phoenix/frontend/python/updaters/retrieve_core_info.py:63: note:     def __setitem__(self, slice, Iterable[str]) -> None
Found 19 errors in 9 files (checked 9 source files)

[RRepo](Parsl)parsl
(Parsl)parsl/parsl/providers/error.py: error: Duplicate module named 'error' (also at '/home/bew/archive/typed_project/(Parsl)parsl/parsl/launchers/error.py')  [misc]
Found 1 error in 1 file (checked 194 source files)

[RRepo](GelaniNijraj)PyMaterial
(GelaniNijraj)PyMaterial/demo/reveal_test_demo.py:9: error: Name 'QWidget' is not defined  [name-defined]
(GelaniNijraj)PyMaterial/demo/reveal_test_demo.py:31: error: Name 'QApplication' is not defined  [name-defined]
(GelaniNijraj)PyMaterial/demo/radio_button_demo.py:9: error: Name 'QWidget' is not defined  [name-defined]
(GelaniNijraj)PyMaterial/demo/radio_button_demo.py:32: error: Name 'QApplication' is not defined  [name-defined]
(GelaniNijraj)PyMaterial/demo/ripple_test_demo.py:11: error: Name 'QWidget' is not defined  [name-defined]
(GelaniNijraj)PyMaterial/demo/ripple_test_demo.py:36: error: Name 'QApplication' is not defined  [name-defined]
(GelaniNijraj)PyMaterial/demo/checkbox_demo.py:9: error: Name 'QWidget' is not defined  [name-defined]
(GelaniNijraj)PyMaterial/demo/checkbox_demo.py:26: error: Name 'QApplication' is not defined  [name-defined]
(GelaniNijraj)PyMaterial/demo/animation_thread_demo.py:8: error: Name 'MAnimationThread' is not defined  [name-defined]
(GelaniNijraj)PyMaterial/demo/animation_thread_demo.py:9: error: Name 'MValueAnimator' is not defined  [name-defined]
(GelaniNijraj)PyMaterial/demo/animation_thread_demo.py:33: error: Name 'QApplication' is not defined  [name-defined]
(GelaniNijraj)PyMaterial/demo/test.py:9: error: Name 'QWidget' is not defined  [name-defined]
(GelaniNijraj)PyMaterial/demo/test.py:31: error: Name 'QApplication' is not defined  [name-defined]
(GelaniNijraj)PyMaterial/demo/fluent_animations_demo.py:33: error: Name 'QWidget' is not defined  [name-defined]
(GelaniNijraj)PyMaterial/demo/fluent_animations_demo.py:103: error: Name 'QApplication' is not defined  [name-defined]
(GelaniNijraj)PyMaterial/MAnimations/MAnimator.py:11: error: Name 'MAnimationThread' is not defined  [name-defined]
Found 16 errors in 8 files (checked 20 source files)

[RRepo](zyga)textland
(zyga)textland/textland/display.py:24: error: No parent module -- cannot perform relative import  [misc]
Found 1 error in 1 file (checked 10 source files)

[RRepo](autokey-py3)autokey
(autokey-py3)autokey/lib/autokey/gtkui/notifier.py:28: error: No parent module -- cannot perform relative import  [misc]
(autokey-py3)autokey/lib/autokey/gtkui/notifier.py:29: error: No parent module -- cannot perform relative import  [misc]
(autokey-py3)autokey/lib/autokey/gtkui/notifier.py:30: error: No parent module -- cannot perform relative import  [misc]
Found 3 errors in 1 file (checked 3 source files)

[RRepo](dylanbstorey)angreal
(dylanbstorey)angreal/setup.py:19: error: Not all arguments converted during string formatting  [str-format]
(dylanbstorey)angreal/tests/unit/integrations/test_git.py:21: error: Name 'test_git_1' already defined on line 11  [no-redef]
(dylanbstorey)angreal/angreal/cli/list_cmd.py:68: error: Module has no attribute "command"  [attr-defined]
(dylanbstorey)angreal/angreal/cli/list_cmd.py:69: error: Module has no attribute "argument"  [attr-defined]
(dylanbstorey)angreal/tests/unit/test_utils.py:6: error: Module 'angreal' has no attribute 'warn'  [attr-defined]
(dylanbstorey)angreal/tests/unit/test_utils.py:6: error: Module 'angreal' has no attribute 'win'  [attr-defined]
(dylanbstorey)angreal/tests/unit/test_utils.py:6: error: Module 'angreal' has no attribute 'error'  [attr-defined]

[RRepo](biplap-sarkar)pylimit
Success: no issues found in 3 source files

[RRepo](zsims)dic
(zsims)dic/dic/container.py:5: error: No parent module -- cannot perform relative import  [misc]
(zsims)dic/dic/container.py:6: error: No parent module -- cannot perform relative import  [misc]
Found 2 errors in 1 file (checked 7 source files)

[RRepo](lyft)incubator-airflow
(lyft)incubator-airflow/airflow/utils/decorators.py: error: Duplicate module named 'decorators' (also at '/home/bew/archive/typed_project/(lyft)incubator-airflow/airflow/www/decorators.py')  [misc]
Found 1 error in 1 file (checked 773 source files)

[RRepo](mikesmth)pi-dashboard
(mikesmth)pi-dashboard/lib/plugins/netatmo.py:109: error: The return type of "__init__" must be None  [misc]
(mikesmth)pi-dashboard/lib/utils.py:24: error: Module 'urllib' has no attribute 'urlencode'  [attr-defined]
(mikesmth)pi-dashboard/lib/utils.py:29: error: Incompatible types in assignment (expression has type "Callable[[Dict[_KT, _VT], _KT, _VT], None]", base class "object" defined the type as "Callable[[object, str, Any], None]")  [assignment]
Found 3 errors in 2 files (checked 25 source files)

[RRepo](berkmancenter)mediacloud
(berkmancenter)mediacloud/mediacloud/mediawords/util/process.py: error: Duplicate module named 'process' (also at '/home/bew/archive/typed_project/(berkmancenter)mediacloud/mediacloud/mediawords/dbi/stories/process.py')  [misc]
(berkmancenter)mediacloud/mediacloud/mediawords/util/process.py: error: Are you missing an __init__.py?  [misc]
Found 2 errors in 1 file (checked 214 source files)

[RRepo](TankerApp)tsrc
(TankerApp)tsrc/tsrc/test/helpers/cli.py: error: Duplicate module named 'cli' (also at '/home/bew/archive/typed_project/(TankerApp)tsrc/tsrc/cli/__init__.py')  [misc]
(TankerApp)tsrc/tsrc/test/helpers/cli.py: error: Are you missing an __init__.py?  [misc]
Found 2 errors in 1 file (checked 47 source files)

[RRepo](PennyDreadfulMTG)Penny-Dreadful-Tools
(PennyDreadfulMTG)Penny-Dreadful-Tools/shared/redis.py:6: error: No parent module -- cannot perform relative import  [misc]
Found 1 error in 1 file (checked 199 source files)

[RRepo](rhinstaller)anaconda
(rhinstaller)anaconda/pyanaconda/payload/errors.py: error: Duplicate module named 'errors' (also at '/home/bew/archive/typed_project/(rhinstaller)anaconda/pyanaconda/errors.py')  [misc]
(rhinstaller)anaconda/pyanaconda/payload/errors.py: error: Are you missing an __init__.py?  [misc]
Found 2 errors in 1 file (checked 343 source files)

[RRepo](chengsoonong)acton
(chengsoonong)acton/acton/proto/io.py:14: error: Name 'Protobuf' is not defined  [name-defined]
(chengsoonong)acton/acton/proto/io.py:72: error: Name 'Protobuf' is not defined  [name-defined]
(chengsoonong)acton/acton/proto/io.py:133: error: Invalid type comment or annotation  [valid-type]
(chengsoonong)acton/acton/proto/io.py:171: error: Invalid type comment or annotation  [valid-type]
(chengsoonong)acton/acton/labellers.py:133: error: Argument 1 of "query" is incompatible with supertype "Labeller"; supertype defines the argument type as "int"  [override]
(chengsoonong)acton/tests/test_proto_io.py:40: error: The return type of a generator function should be "Generator" or one of its supertypes  [misc]
(chengsoonong)acton/acton/cli.py:66: error: On Python 3 '{}'.format(b'abc') produces "b'abc'"; use !r if this is a desired behavior  [str-bytes-safe]
(chengsoonong)acton/acton/cli.py:301: error: Need type annotation for 'labelled_ids' (hint: "labelled_ids: List[<type>] = ...")  [var-annotated]
(chengsoonong)acton/acton/plot.py:24: error: Argument 1 to "len" has incompatible type "Iterable[Any]"; expected "Sized"  [arg-type]
(chengsoonong)acton/acton/plot.py:44: error: "Iterator[Any]" has no attribute "shape"  [attr-defined]
(chengsoonong)acton/acton/plot.py:45: error: Value of type "Iterator[Any]" is not indexable  [index]
(chengsoonong)acton/acton/plot.py:47: error: "Iterator[Any]" has no attribute "argmax"  [attr-defined]
Found 12 errors in 5 files (checked 14 source files)

[RRepo](rachekalmir)pyJolt
(rachekalmir)pyJolt/pyjolt/transforms/shiftr.py:146: error: Need type annotation for 'process_queue'  [var-annotated]
(rachekalmir)pyJolt/pyjolt/transforms/shiftr.py:156: error: Name 'spec' already defined on line 143  [no-redef]
(rachekalmir)pyJolt/pyjolt/transforms/shiftr.py:156: error: Name 'data' already defined on line 143  [no-redef]
(rachekalmir)pyJolt/pyjolt/transforms/shiftr.py:159: error: "Dict[Any, Any]" has no attribute "value"; maybe "values"?  [attr-defined]
(rachekalmir)pyJolt/pyjolt/transforms/shiftr.py:175: error: "Dict[Any, Any]" has no attribute "path"  [attr-defined]
(rachekalmir)pyJolt/pyjolt/transforms/shiftr.py:175: error: Argument 1 to "process_sub_amp" has incompatible type "Dict[Any, Any]"; expected "TreeManager"  [arg-type]
(rachekalmir)pyJolt/pyjolt/transforms/shiftr.py:177: error: Argument 1 to "process_sub_amp" has incompatible type "Dict[Any, Any]"; expected "TreeManager"  [arg-type]
(rachekalmir)pyJolt/pyjolt/transforms/shiftr.py:179: error: "Dict[Any, Any]" has no attribute "value"; maybe "values"?  [attr-defined]
(rachekalmir)pyJolt/pyjolt/transforms/shiftr.py:180: error: Argument 1 to "process_rhs" has incompatible type "Dict[Any, Any]"; expected "TreeManager"  [arg-type]
(rachekalmir)pyJolt/pyjolt/transforms/shiftr.py:185: error: "Dict[Any, Any]" has no attribute "path"  [attr-defined]
(rachekalmir)pyJolt/pyjolt/transforms/shiftr.py:189: error: Argument 1 to "process_sub_amp" has incompatible type "Dict[Any, Any]"; expected "TreeManager"  [arg-type]
(rachekalmir)pyJolt/pyjolt/transforms/shiftr.py:189: error: Argument 2 to "process_sub_amp" has incompatible type "Dict[Any, Any]"; expected "TreeManager"  [arg-type]
(rachekalmir)pyJolt/pyjolt/transforms/shiftr.py:197: error: "Dict[Any, Any]" has no attribute "value"; maybe "values"?  [attr-defined]
(rachekalmir)pyJolt/pyjolt/transforms/shiftr.py:198: error: Argument 1 to "process_rhs" has incompatible type "Dict[Any, Any]"; expected "TreeManager"  [arg-type]
(rachekalmir)pyJolt/pyjolt/transforms/shiftr.py:200: error: "Dict[Any, Any]" has no attribute "value"; maybe "values"?  [attr-defined]
(rachekalmir)pyJolt/pyjolt/transforms/shiftr.py:201: error: Argument 1 to "process_rhs" has incompatible type "Dict[Any, Any]"; expected "TreeManager"  [arg-type]
(rachekalmir)pyJolt/pyjolt/transforms/shiftr.py:201: error: "Dict[Any, Any]" has no attribute "value"; maybe "values"?  [attr-defined]

[RRepo](blockauth)smart-contract
Success: no issues found in 1 source file

[RRepo](spectra-cluster)spectra-cluster-py
(spectra-cluster)spectra-cluster-py/spectra_cluster/clustering_parser.py:8: error: No parent module -- cannot perform relative import  [misc]
Found 1 error in 1 file (checked 32 source files)

[RRepo](Aluriak)PowerGrASP
(Aluriak)PowerGrASP/powergrasp/__main__.py:5: error: No parent module -- cannot perform relative import  [misc]
Found 1 error in 1 file (checked 16 source files)

[RRepo](alexbielen)chainsmoke
(alexbielen)chainsmoke/chainsmoke/decide.py:39: error: Name 'Decision' already defined on line 28  [no-redef]
(alexbielen)chainsmoke/chainsmoke/decide.py:73: error: Item "Decision" of "Union[Decision, Action]" has no attribute "next"  [union-attr]
(alexbielen)chainsmoke/chainsmoke/decide.py:73: error: Item "Action" of "Union[Decision, Action]" has no attribute "next"  [union-attr]
(alexbielen)chainsmoke/chainsmoke/decide.py:76: error: Name 'Action' already defined on line 32  [no-redef]

[RRepo](JZQT)aioqiniu
(JZQT)aioqiniu/tests/services/test_storage.py:9: error: Relative import climbs too many namespaces  [misc]
Found 1 error in 1 file (checked 8 source files)

[RRepo](petervaro)cutils
(petervaro)cutils/internal/singly_linked_list.py:34: error: Module 'types' has no attribute 'C_TYPES'  [attr-defined]
(petervaro)cutils/internal/dynamic_array.py:34: error: Module 'types' has no attribute 'C_TYPES'  [attr-defined]
(petervaro)cutils/pycutils/cutils/cenv.py:143: error: Incompatible types in assignment (expression has type "Tuple[]", variable has type "List[str]")  [assignment]
(petervaro)cutils/pycutils/cutils/cenv.py:156: error: Argument 1 to "join" of "str" has incompatible type "StackSummary"; expected "Iterable[str]"  [arg-type]
(petervaro)cutils/pycutils/cutils/cenv.py:156: note: Following member(s) of "StackSummary" have conflicts:
(petervaro)cutils/pycutils/cutils/cenv.py:156: note:     Expected:
(petervaro)cutils/pycutils/cutils/cenv.py:156: note:         def __iter__(self) -> Iterator[str]
(petervaro)cutils/pycutils/cutils/cenv.py:156: note:     Got:
(petervaro)cutils/pycutils/cutils/cenv.py:156: note:         def __iter__(self) -> Iterator[FrameSummary]
(petervaro)cutils/internal/static_hash_map.py:35: error: Module 'types' has no attribute 'C_TYPES'  [attr-defined]
(petervaro)cutils/pycutils/cutils/cver.py:86: error: Name 'fodler' is not defined  [name-defined]
(petervaro)cutils/internal/convert.py:42: error: "object" has no attribute "items"  [attr-defined]
(petervaro)cutils/internal/convert.py:43: error: Unsupported target for indexed assignment  [index]
(petervaro)cutils/internal/convert.py:45: error: Unsupported target for indexed assignment  [index]
(petervaro)cutils/internal/convert.py:45: error: "object" has no attribute "pop"  [attr-defined]
(petervaro)cutils/internal/convert.py:63: error: Too many arguments for "dict_to_plist"  [call-arg]
Found 11 errors in 6 files (checked 14 source files)

[RRepo](mayfield)shellish
(mayfield)shellish/shellish/session.py:15: error: No parent module -- cannot perform relative import  [misc]
Found 1 error in 1 file (checked 36 source files)

[RRepo](philiplessner)USPTOAPI
Success: no issues found in 5 source files

[RRepo](status-im)status-network-token
Success: no issues found in 1 source file

[RRepo](Ulauncher)Ulauncher
(Ulauncher)Ulauncher/ulauncher/api/client/setup_logging.py: error: Duplicate module named 'setup_logging' (also at '/home/bew/archive/typed_project/(Ulauncher)Ulauncher/ulauncher/utils/setup_logging.py')  [misc]
(Ulauncher)Ulauncher/ulauncher/api/client/setup_logging.py: error: Are you missing an __init__.py?  [misc]
Found 2 errors in 1 file (checked 148 source files)

[RRepo](mitmedialab)MediaCloud-Web-Tools
(mitmedialab)MediaCloud-Web-Tools/server/views/sources/apicache.py: error: Duplicate module named 'apicache' (also at '/home/bew/archive/typed_project/(mitmedialab)MediaCloud-Web-Tools/server/views/apicache.py')  [misc]
(mitmedialab)MediaCloud-Web-Tools/server/views/sources/apicache.py: error: Are you missing an __init__.py?  [misc]
Found 2 errors in 1 file (checked 64 source files)

[RRepo](Svolcano)python_exercise
(Svolcano)python_exercise/WinLsLoad/SvrConfig.py:22: error: invalid syntax  [syntax]
Found 1 error in 1 file (checked 236 source files)

[RRepo](actionless)oomox
(actionless)oomox/plugins/theme_materia/oomox_plugin.py: error: Duplicate module named 'oomox_plugin' (also at '/home/bew/archive/typed_project/(actionless)oomox/plugins/theme_arc/oomox_plugin.py')  [misc]
Found 1 error in 1 file (checked 27 source files)

[RRepo](morganbengtsson)microreader
(morganbengtsson)microreader/favicon.py:5: error: Module 'urllib.request' has no attribute 'urlparse'  [attr-defined]
(morganbengtsson)microreader/favicon.py:8: error: Name 'Request' already defined (possibly by an import)  [no-redef]
(morganbengtsson)microreader/favicon.py:8: error: Name 'urlopen' already defined (possibly by an import)  [no-redef]
(morganbengtsson)microreader/favicon.py:9: error: Module 'urllib' has no attribute 'urlretrieve'  [attr-defined]
(morganbengtsson)microreader/favicon.py:9: error: Name 'urlretrieve' already defined (possibly by an import)  [no-redef]
(morganbengtsson)microreader/models.py:12: error: Name 'SqliteDatabase' is not defined  [name-defined]
(morganbengtsson)microreader/models.py:33: error: Name 'Model' is not defined  [name-defined]
(morganbengtsson)microreader/models.py:38: error: Name 'TextField' is not defined  [name-defined]
(morganbengtsson)microreader/models.py:39: error: Name 'DateTimeField' is not defined  [name-defined]
(morganbengtsson)microreader/models.py:40: error: Name 'DateTimeField' is not defined  [name-defined]
(morganbengtsson)microreader/models.py:41: error: Name 'TextField' is not defined  [name-defined]
(morganbengtsson)microreader/models.py:42: error: Name 'TextField' is not defined  [name-defined]
(morganbengtsson)microreader/models.py:43: error: Name 'IntegerField' is not defined  [name-defined]
(morganbengtsson)microreader/models.py:44: error: Name 'IntegerField' is not defined  [name-defined]
(morganbengtsson)microreader/models.py:131: error: Name 'TextField' is not defined  [name-defined]
(morganbengtsson)microreader/models.py:132: error: Name 'TextField' is not defined  [name-defined]
(morganbengtsson)microreader/models.py:133: error: Name 'TextField' is not defined  [name-defined]
(morganbengtsson)microreader/models.py:134: error: Name 'TextField' is not defined  [name-defined]
(morganbengtsson)microreader/models.py:135: error: Name 'TextField' is not defined  [name-defined]
(morganbengtsson)microreader/models.py:136: error: Name 'BooleanField' is not defined  [name-defined]
(morganbengtsson)microreader/models.py:137: error: Name 'BooleanField' is not defined  [name-defined]
(morganbengtsson)microreader/models.py:138: error: Name 'BooleanField' is not defined  [name-defined]
(morganbengtsson)microreader/models.py:139: error: Name 'ForeignKeyField' is not defined  [name-defined]
(morganbengtsson)microreader/models.py:140: error: Name 'DateTimeField' is not defined  [name-defined]
(morganbengtsson)microreader/models.py:141: error: Name 'DateTimeField' is not defined  [name-defined]
(morganbengtsson)microreader/microreader.py:7: error: Name 'urlunsplit' already defined (possibly by an import)  [no-redef]
(morganbengtsson)microreader/microreader.py:8: error: Module 'urllib' has no attribute 'urlencode'  [attr-defined]
(morganbengtsson)microreader/microreader.py:8: error: Name 'urlencode' already defined (possibly by an import)  [no-redef]
(morganbengtsson)microreader/microreader.py:53: error: Name 'favicon' already defined (by an import)  [no-redef]
(morganbengtsson)microreader/microreader.py:61: error: Name 'DateField' is not defined  [name-defined]
(morganbengtsson)microreader/microreader.py:142: error: Incompatible return value type (got "Dict[str, List[Any]]", expected "str")  [return-value]
(morganbengtsson)microreader/microreader.py:154: error: Incompatible return value type (got "Dict[str, Any]", expected "str")  [return-value]
(morganbengtsson)microreader/microreader.py:176: error: Incompatible return value type (got "Dict[str, Any]", expected "str")  [return-value]
(morganbengtsson)microreader/microreader.py:185: error: Incompatible return value type (got "Dict[str, Any]", expected "str")  [return-value]
(morganbengtsson)microreader/microreader.py:255: error: Name 'update_channels' already defined on line 243  [no-redef]
Found 35 errors in 3 files (checked 3 source files)

[RRepo](RIP95)kurisu-bot
(RIP95)kurisu-bot/addons/checks/checks.py:2: error: Module 'addons.checks' has no attribute 'errors'  [attr-defined]

[RRepo](angstromctf)djangoctf
(angstromctf)djangoctf/api/serializers.py:8: error: No parent module -- cannot perform relative import  [misc]
Found 1 error in 1 file (checked 11 source files)

[RRepo](Pittsburgh-NEH-Institute)Institute-Materials-2017
(Pittsburgh-NEH-Institute)Institute-Materials-2017/schedule/week_2/collation_with_markup/xml_and_python.py:70: error: Name 'collate' is not defined  [name-defined]
(Pittsburgh-NEH-Institute)Institute-Materials-2017/schedule/week_2/collation_with_markup/xml_and_python.py:71: error: Name 'collate' is not defined  [name-defined]
(Pittsburgh-NEH-Institute)Institute-Materials-2017/schedule/week_2/collation_with_markup/xml_and_python.py:74: error: Name 'collate' is not defined  [name-defined]
(Pittsburgh-NEH-Institute)Institute-Materials-2017/schedule/week_2/collation_with_markup/xml_and_python.py:75: error: Name 'collate' is not defined  [name-defined]
(Pittsburgh-NEH-Institute)Institute-Materials-2017/schedule/week_2/collation_with_markup/xml_and_python.py:76: error: Name 'collate' is not defined  [name-defined]
Found 5 errors in 1 file (checked 12 source files)

[RRepo](Nic30)hwtLib
(Nic30)hwtLib/hwtLib/peripheral/uart/intf.py: error: Duplicate module named 'intf' (also at '/home/bew/archive/typed_project/(Nic30)hwtLib/hwtLib/peripheral/i2c/intf.py')  [misc]
Found 1 error in 1 file (checked 295 source files)

[RRepo](nkantar)Parsenvy
Success: no issues found in 2 source files

[RRepo](olist)correios
(olist)correios/correios/serializers.py:18: error: No parent module -- cannot perform relative import  [misc]
Found 1 error in 1 file (checked 21 source files)

[RRepo](rr-)drill
(rr-)drill/drillsrs/cmd/stats.py:162: error: Argument 1 to "HistoryItem" has incompatible type "date"; expected "datetime"  [arg-type]
(rr-)drill/drillsrs/cmd/stats.py:184: error: "Template" has no attribute "globals"  [attr-defined]
(rr-)drill/drillsrs/cmd/stats.py:185: error: "Template" has no attribute "globals"  [attr-defined]
(rr-)drill/drillsrs/cmd/stats.py:186: error: "Template" has no attribute "globals"  [attr-defined]
Found 4 errors in 1 file (checked 23 source files)

[RRepo](RRZE-HPC)kerncraft
(RRZE-HPC)kerncraft/kerncraft/likwid_bench_auto.py:112: error: Incompatible types in assignment (expression has type "List[str]", target has type "str")  [assignment]
(RRZE-HPC)kerncraft/kerncraft/likwid_bench_auto.py:117: error: Incompatible types in assignment (expression has type "Dict[str, str]", target has type "str")  [assignment]
(RRZE-HPC)kerncraft/kerncraft/likwid_bench_auto.py:128: error: Incompatible types in assignment (expression has type "int", target has type "str")  [assignment]
(RRZE-HPC)kerncraft/kerncraft/likwid_bench_auto.py:132: error: Incompatible types in assignment (expression has type "int", target has type "str")  [assignment]
(RRZE-HPC)kerncraft/kerncraft/likwid_bench_auto.py:133: error: Incompatible types in assignment (expression has type "Dict[str, str]", target has type "str")  [assignment]
(RRZE-HPC)kerncraft/kerncraft/roofline-plot.py:53: error: Value of type "object" is not indexable  [index]
(RRZE-HPC)kerncraft/kerncraft/roofline-plot.py:59: error: Value of type "object" is not indexable  [index]
(RRZE-HPC)kerncraft/kerncraft/roofline-plot.py:60: error: Value of type "object" is not indexable  [index]
Found 8 errors in 2 files (checked 24 source files)

[RRepo](edio)randrctl
(edio)randrctl/randrctl/exception.py:49: error: Incompatible types in assignment (expression has type "List[Any]", variable has type "Tuple[Any, ...]")  [assignment]
(edio)randrctl/randrctl/context.py:72: error: No overload variant of "get" of "Mapping" matches argument types "str", "Dict[<nothing>, <nothing>]"  [call-overload]
(edio)randrctl/randrctl/context.py:72: note: Possible overload variant:
(edio)randrctl/randrctl/context.py:72: note:     def [_T] get(self, k: <nothing>, default: _T) -> _T
(edio)randrctl/randrctl/context.py:72: note:     <1 more non-matching overload not shown>
(edio)randrctl/randrctl/context.py:73: error: No overload variant of "get" of "Mapping" matches argument types "str", "Dict[<nothing>, <nothing>]"  [call-overload]
(edio)randrctl/randrctl/context.py:73: note: Possible overload variant:
(edio)randrctl/randrctl/context.py:73: note:     def [_T] get(self, k: <nothing>, default: _T) -> _T
(edio)randrctl/randrctl/context.py:73: note:     <1 more non-matching overload not shown>
(edio)randrctl/randrctl/context.py:74: error: No overload variant of "get" of "Mapping" matches argument types "str", "Dict[<nothing>, <nothing>]"  [call-overload]
(edio)randrctl/randrctl/context.py:74: note: Possible overload variant:
(edio)randrctl/randrctl/context.py:74: note:     def [_T] get(self, k: <nothing>, default: _T) -> _T
(edio)randrctl/randrctl/context.py:74: note:     <1 more non-matching overload not shown>
Found 4 errors in 2 files (checked 11 source files)

[RRepo](viraja1)grammar-check
(viraja1)grammar-check/grammar_check/main.py:8: error: No parent module -- cannot perform relative import  [misc]
(viraja1)grammar-check/grammar_check/main.py:9: error: No parent module -- cannot perform relative import  [misc]
(viraja1)grammar-check/grammar_check/main.py:10: error: No parent module -- cannot perform relative import  [misc]
(viraja1)grammar-check/grammar_check/main.py:11: error: No parent module -- cannot perform relative import  [misc]
(viraja1)grammar-check/grammar_check/main.py:12: error: No parent module -- cannot perform relative import  [misc]
Found 5 errors in 1 file (checked 7 source files)

[RRepo](azavea)raster-foundry
(azavea)raster-foundry/app-tasks/rf/src/rf/utils/io.py: error: Duplicate module named 'io' (also at '/home/bew/archive/typed_project/(azavea)raster-foundry/app-tasks/rf/src/rf/ingest/io.py')  [misc]
Found 1 error in 1 file (checked 12 source files)

[RRepo](USTB-LETTers)judger
Success: no issues found in 6 source files

[RRepo](bittremieux)ANN-SoLo
(bittremieux)ANN-SoLo/src/ann_solo/writer.py:13: error: No parent module -- cannot perform relative import  [misc]
Found 1 error in 1 file (checked 7 source files)

[RRepo](UCL-INGI)INGInious
(UCL-INGI)INGInious/inginious/frontend/pages/api/tasks.py: error: Duplicate module named 'tasks' (also at '/home/bew/archive/typed_project/(UCL-INGI)INGInious/inginious/frontend/tasks.py')  [misc]
(UCL-INGI)INGInious/inginious/frontend/pages/api/tasks.py: error: Are you missing an __init__.py?  [misc]
Found 2 errors in 1 file (checked 114 source files)

[RRepo](douglasmiranda)django-fine-uploader
(douglasmiranda)django-fine-uploader/django_fine_uploader/fineuploader.py:9: error: No parent module -- cannot perform relative import  [misc]
(douglasmiranda)django-fine-uploader/django_fine_uploader/fineuploader.py:10: error: No parent module -- cannot perform relative import  [misc]
Found 2 errors in 1 file (checked 11 source files)

